<?xml version="1.0"?>
<!--

  Copyright (c) 2011, PAL Robotics, S.L.
  All rights reserved.

  This work is licensed under the Creative Commons Attribution-NonCommercial-NoDerivs 3.0 Unported License.
  To view a copy of this license, visit http://creativecommons.org/licenses/by-nc-nd/3.0/ or send a letter to
  Creative Commons, 444 Castro Street, Suite 900, Mountain View, California, 94041, USA.
-->
<robot xmlns:sensor="http://playerstage.sourceforge.net/gazebo/xmlschema/#sensor"
      xmlns:controller="http://playerstage.sourceforge.net/gazebo/xmlschema/#controller"
      xmlns:interface="http://playerstage.sourceforge.net/gazebo/xmlschema/#interface"
      xmlns:xacro="http://ros.org/wiki/xacro">

  <include filename="$(find reem_description)/urdf/deg_to_rad.xacro" />
  <include filename="$(find reem_description)/urdf/hand/hand.gazebo.xacro" />
  <include filename="$(find reem_description)/urdf/hand/hand.transmission.xacro" />

  <xacro:property name="hand_friction" value="0.0" /> <!--TODO: Tune-->
  <xacro:property name="hand_damping"  value="0.5" /> <!--TODO: Tune-->
  <xacro:property name="hand_max_vel" value="1.0" />

  <xacro:macro name="reem_finger" params="hand_name hand_side hand_reflect finger_name finger_reflect">
    <joint name="${hand_name}_${hand_side}_${finger_name}_1_joint" type="revolute">
      <parent link="${hand_name}_${hand_side}_palm_link" />
      <child link="${hand_name}_${hand_side}_${finger_name}_1_link" />
      <origin xyz="0.101 ${reflect * 0.0025} ${finger_reflect * 0.0165}" rpy="${(90.0 - reflect * 90.0) * deg_to_rad} 0 ${reflect * 90.0 * deg_to_rad}" />
      <axis xyz="0 0 1" />
      <limit lower="${0.0 * deg_to_rad}" upper="${90.0 * deg_to_rad}" effort="2.0" velocity="${hand_max_vel}" />
      <dynamics friction="${hand_friction}" damping="${hand_damping}"/>
    </joint>

    <link name="${hand_name}_${hand_side}_${finger_name}_1_link">
      <inertial>
        <origin xyz="0 0 0" rpy="0 0 0" /> <!--TODO: Fill up-->
        <mass value="0.05" />
        <inertia ixx="0"  ixy="0"  ixz="0" iyy="0" iyz="0" izz="0" /> <!--TODO: Fill up-->
      </inertial>
      <visual>
        <origin xyz="0 0 0" rpy="0 0 0" />
        <geometry>
          <mesh filename="package://reem_description/meshes/hand/hand_finger_1.dae" scale="1 1 ${-reflect * finger_reflect}" />
        </geometry>
        <material name="LightGrey" />
      </visual>
      <collision>
        <origin xyz="0 0 0" rpy="0 0 0" />
        <geometry>
          <mesh filename="package://reem_description/meshes/hand/hand_finger_1_collision.stl" scale="1 1 ${-reflect * finger_reflect}" />
        </geometry>
      </collision>
    </link>

    <joint name="${hand_name}_${hand_side}_${finger_name}_2_joint" type="revolute">
      <parent link="${hand_name}_${hand_side}_${finger_name}_1_link" />
      <child link="${hand_name}_${hand_side}_${finger_name}_2_link" />
      <origin xyz="0.00357 -0.04084 0" rpy="0 0 0" />
      <axis xyz="0 0 1" />
      <limit lower="${0.0 * deg_to_rad}" upper="${80.0 * deg_to_rad}" effort="1.0" velocity="${hand_max_vel}" />
      <dynamics friction="${hand_friction}" damping="${hand_damping}"/>
    </joint>

    <link name="${hand_name}_${hand_side}_${finger_name}_2_link">
      <inertial>
        <origin xyz="0 0 0" rpy="0 0 0" /> <!--TODO: Fill up-->
        <mass value="0.05" />
        <inertia ixx="0"  ixy="0"  ixz="0" iyy="0" iyz="0" izz="0" /> <!--TODO: Fill up-->
      </inertial>
      <visual>
        <origin xyz="0 0 0" rpy="0 0 0" />
        <geometry>
          <mesh filename="package://reem_description/meshes/hand/hand_finger_2.dae" scale="1 1 ${-reflect * finger_reflect }" />
        </geometry>
        <material name="LightGrey" />
      </visual>
      <collision>
        <origin xyz="0 0 0" rpy="0 0 0" />
        <geometry>
          <mesh filename="package://reem_description/meshes/hand/hand_finger_2_collision.stl" scale="1 1 ${-reflect * finger_reflect}" />
        </geometry>
      </collision>
    </link>

    <joint name="${hand_name}_${hand_side}_${finger_name}_3_joint" type="revolute">
      <parent link="${hand_name}_${hand_side}_${finger_name}_2_link" />
      <child link="${hand_name}_${hand_side}_${finger_name}_3_link" />
      <origin xyz="0.00572 -0.0269 0" rpy="0 0 0" />
      <axis xyz="0 0 1" />
      <limit lower="${0.0 * deg_to_rad}" upper="${80.0 * deg_to_rad}" effort="1.0" velocity="${hand_max_vel}" />
      <limit lower="${0.0 * deg_to_rad}" upper="${1.0 * deg_to_rad}" effort="1.0" velocity="${hand_max_vel}" />
      <dynamics friction="${hand_friction}" damping="${hand_damping}"/>
    </joint>

    <link name="${hand_name}_${hand_side}_${finger_name}_3_link">
      <inertial>
        <origin xyz="0 0 0" rpy="0 0 0" /> <!--TODO: Fill up-->
        <mass value="0.05" />
        <inertia ixx="0"  ixy="0"  ixz="0" iyy="0" iyz="0" izz="0" /> <!--TODO: Fill up-->
      </inertial>
      <visual>
        <origin xyz="0 0 0" rpy="0 0 0" />
        <geometry>
          <mesh filename="package://reem_description/meshes/hand/hand_finger_3.dae" scale="1 1 ${-reflect * finger_reflect}" />
        </geometry>
        <material name="LightGrey" />
      </visual>
      <collision>
        <origin xyz="0 0 0" rpy="0 0 0" />
        <geometry>
          <mesh filename="package://reem_description/meshes/hand/hand_finger_3_collision.stl" scale="1 1 ${-reflect * finger_reflect}" />
        </geometry>
      </collision>
    </link>

    <xacro:hand_gazebo              name="${hand_name}_${hand_side}_${finger_name}_1"/>
    <xacro:hand_gazebo              name="${hand_name}_${hand_side}_${finger_name}_2"/>
    <xacro:hand_gazebo              name="${hand_name}_${hand_side}_${finger_name}_3"/>
    <xacro:hand_simple_transmission name="${hand_name}_${hand_side}_${finger_name}_1" reduction="200"/>
    <xacro:hand_simple_transmission name="${hand_name}_${hand_side}_${finger_name}_2" reduction="200"/>
    <xacro:hand_simple_transmission name="${hand_name}_${hand_side}_${finger_name}_3" reduction="200"/>
  </xacro:macro>


  <xacro:macro name="reem_hand" params="name parent side reflect">

    <!-- Palm -->
    <joint name="${name}_${side}_palm_joint" type="fixed">
      <parent link="${parent}" />
      <child link="${name}_${side}_palm_link" />
      <origin xyz="0 0 0" rpy="0 0 0" />
    </joint>

    <link name="${name}_${side}_palm_link">
      <inertial>
        <!--<origin xyz="0.07547 ${-reflect * 0.00468} 0.00291" rpy="0 0 0" />-->
        <origin xyz="0 ${-reflect * 0.07547} 0 " rpy="0 0 0" /> <!--TODO: This does not make sense!, there must be a bug in how Gazebo bungles the CoM of a chain of fixed joints-->
        <mass value="0.41066" /> <!--NOTE: Assigning 0.05kg to each of the ten phalanxes-->
        <inertia ixx="0"  ixy="0"  ixz="0" iyy="0" iyz="0" izz="0" />
      </inertial>
      <visual>
        <origin xyz="0 0 0" rpy="0 0 0" />
        <geometry>
          <mesh filename="package://reem_description/meshes/hand/hand_palm.dae" scale="1 ${-reflect} 1" />
        </geometry>
        <material name="LightGrey" />
      </visual>
      <collision>
        <origin xyz="0 0 0" rpy="0 0 0" />
        <geometry>
          <mesh filename="package://reem_description/meshes/hand/hand_palm_collision.stl" scale="1 ${-reflect} 1" />
        </geometry>
      </collision>
    </link>

    <xacro:hand_gazebo name="${name}_${side}_palm"/>

    <!-- Thumb -->
    <joint name="${name}_${side}_thumb_joint" type="revolute">
      <parent link="${name}_${side}_palm_link" />
      <child link="${name}_${side}_thumb_link" />
      <!-- added 10mm offset along y-axis -->
      <origin xyz="0.03649 ${reflect*0.008 + reflect*0.010}  0.02" rpy="${(90.0 + reflect * 90.0) * deg_to_rad} ${(90.0 + 13) * deg_to_rad} ${reflect * 13.0 * deg_to_rad}" />
      <axis xyz="0 0 1" />
<!--       <limit lower="${0.0 * deg_to_rad}" upper="${92.0 * deg_to_rad}" effort="2.0" velocity="${hand_max_vel}" /> -->
      <limit lower="${0.0 * deg_to_rad}" upper="${90.0 * deg_to_rad}" effort="2.0" velocity="${hand_max_vel}" /> <!--TODO: Restore!-->
      <dynamics friction="${hand_friction}" damping="${hand_damping}"/>
    </joint>

    <link name="${name}_${side}_thumb_link">
      <inertial>
        <origin xyz="0 0 0" rpy="0 0 0" /> <!--TODO: Fill up-->
        <mass value="0.05" />
        <inertia ixx="0"  ixy="0"  ixz="0" iyy="0" iyz="0" izz="0" /> <!--TODO: Fill up-->
      </inertial>
      <visual>
        <origin xyz="0 0 0" rpy="0 0 0" />
        <geometry>
          <mesh filename="package://reem_description/meshes/hand/hand_thumb.dae" scale="1 1 ${-reflect}" />
        </geometry>
        <material name="LightGrey" />
      </visual>
      <collision>
        <origin xyz="0 0 0" rpy="0 0 0" />
        <geometry>
          <mesh filename="package://reem_description/meshes/hand/hand_thumb_collision.stl" scale="1 1 ${-reflect}" />
        </geometry>
      </collision>
    </link>

   <!-- Temporary visual for 10mm thumb offset -->
   <!-- (there is no collision geometry, but you must still disable collision checking for this link) -->
    <joint name="${name}_${side}_thumb_extension_joint" type="fixed">
      <parent link="${name}_${side}_thumb_link" />
      <child link="${name}_${side}_thumb_extension_link" />
      <origin xyz="-0.014 -0.002 ${reflect*0.008}" rpy="0 0 0" /> <!-- centered in middle of the gap, 8mm back, 2mm down -->
      <axis xyz="0 0 1" />
    </joint>
    <link name="${name}_${side}_thumb_extension_link">
      <inertial>
        <origin xyz="0 0 0" rpy="0 0 0" />
        <mass value="0.01" />
        <inertia ixx="0"  ixy="0"  ixz="0" iyy="0" iyz="0" izz="0" /> 
      </inertial>
      <visual>
        <origin xyz="0 0 0" rpy="0 0 0" />
        <geometry>
          <box size="0.012 0.015 0.015"/> <!-- visual is 12mm long and 16mm square -->
        </geometry>
        <material name="White" />
      </visual>
    </link>

    <xacro:hand_gazebo name="${name}_${side}_thumb"/>
    <xacro:hand_simple_transmission name="${name}_${side}_thumb" reduction="168" />

    <!-- Index finger -->
    <xacro:reem_finger hand_name="${name}" hand_side="${side}" hand_reflect="${reflect}" finger_name="index" finger_reflect="1"/>

    <!-- Middle finger -->
    <xacro:reem_finger hand_name="${name}" hand_side="${side}" hand_reflect="${reflect}" finger_name="middle" finger_reflect="-1"/>

    <!-- grasping hack -->
    <xacro:hand_grasping_hack side="${side}" />

    <!-- Grasping frame -->
    <!-- grasp planner will approach along x-axis -->
    <joint name="${name}_${side}_grasping_frame_joint" type="fixed">
      <parent link="${name}_${side}_palm_link" />
      <child link="${name}_${side}_grasping_frame" />
      <origin xyz="0.0 ${reflect * 0.054} 0.018" rpy="0 0 0" />
    </joint>
    <link name="${name}_${side}_grasping_frame">
      <inertial>
        <origin xyz="0 0 0" rpy="0 0 0" />
        <mass value="0.01" />  <!-- matrix below must not be zero, or Gazebo won't load -->
        <inertia ixx="0.1"  ixy="0.0"  ixz="0.0"
                 iyy="0.1"  iyz="0.0"
                 izz="0.1" />
      </inertial>
    </link>

  </xacro:macro>

</robot>
