<?xml version="1.0"?>
<!--

  Copyright (c) 2011, PAL Robotics, S.L.
  All rights reserved.

  This work is licensed under the Creative Commons Attribution-NonCommercial-NoDerivs 3.0 Unported License.
  To view a copy of this license, visit http://creativecommons.org/licenses/by-nc-nd/3.0/ or send a letter to
  Creative Commons, 444 Castro Street, Suite 900, Mountain View, California, 94041, USA.
-->
<robot xmlns:sensor="http://playerstage.sourceforge.net/gazebo/xmlschema/#sensor"
      xmlns:controller="http://playerstage.sourceforge.net/gazebo/xmlschema/#controller"
      xmlns:interface="http://playerstage.sourceforge.net/gazebo/xmlschema/#interface"
      xmlns:xacro="http://ros.org/wiki/xacro">

  <include filename="$(find reem_description)/urdf/deg_to_rad.xacro" />
  <include filename="$(find reem_description)/urdf/head/head.gazebo.xacro" />
  <include filename="$(find reem_description)/urdf/head/head.transmission.xacro" />

  <xacro:property name="head_friction" value="3.0" />
  <xacro:property name="head_damping"  value="0.1" />
  <xacro:property name="head_max_vel"  value="1.0" />

  <xacro:macro name="reem_head_1" params="name parent">
    <!--************************-->
    <!--     HEAD_1 (PAN)       -->
    <!--************************-->
    <link name="${name}_link">
      <inertial>
        <origin xyz="0.01741 0.00466 -0.00434" rpy="0 0 0" />
        <mass value="0.98547" />
        <inertia ixx="1"  ixy="0"  ixz="0" iyy="1" iyz="0" izz="1" />
      </inertial>
      <visual>
        <origin xyz="0 0 0" rpy="0 0 0" />
        <geometry>
          <mesh filename="package://reem_description/meshes/head/head_1_low.stl" />
        </geometry>
        <material name="DarkGrey" />
      </visual>
      <collision>
        <origin xyz="-0.0 0 -0.05" rpy="0 0 0" />
        <geometry>
          <cylinder radius="0.06" length="0.08" />
        </geometry>
      </collision>
    </link>

    <joint name="${name}_joint" type="revolute">
      <parent link="${parent}"/>
        <child link="${name}_link"/>
      <origin xyz="-0.024 -0.412 0" rpy="${90.0 * deg_to_rad} 0 0" />
      <axis xyz="0 0 1" />
      <limit lower="${-75.0 * deg_to_rad}" upper="${75.0 * deg_to_rad}" effort="0.0" velocity="${head_max_vel}" />
      <dynamics damping="${head_damping}" friction="${head_friction}"/> <!--TODO: Tune-->
    </joint>

    <!-- extensions -->
    <xacro:reem_head_1_gazebo name="${name}" />
    <xacro:reem_head_1_transmission name="${name}" />

  </xacro:macro>

  <xacro:macro name="reem_head_2" params="name parent">
    <!--************************-->
    <!--      HEAD_2 (TILT)     -->
    <!--************************-->
    <link name="${name}_link">
      <inertial>
        <origin xyz="-0.04431 -0.13008 0.000011" rpy="0 0 0" />
        <mass value="1.20862" />
        <inertia ixx="1"  ixy="0"  ixz="0" iyy="1" iyz="0" izz="1" />
      </inertial>
      <visual>
        <origin xyz="0 0 0" rpy="0 0 0" />
        <geometry>
          <mesh filename="package://reem_description/meshes/head/head_2_low.stl" />
        </geometry>
        <material name="LightGrey" />
      </visual>
      <collision>
        <origin xyz="0 0 0" rpy="0 0 0" />
        <geometry>
          <mesh filename="package://reem_description/meshes/head/head_2_collision.stl" />
        </geometry>
        <material name="LightGrey" />
      </collision>
    </link>

    <joint name="${name}_joint" type="revolute">
      <parent link="${parent}"/>
        <child link="${name}_link"/>
      <origin xyz="0.0445 0 0" rpy="${-90.0 * deg_to_rad} 0 0" />
      <axis xyz="0 0 1" />
      <limit lower="${-15.0 * deg_to_rad}" upper="${45.0 * deg_to_rad}" effort="0.0" velocity="${head_max_vel}" />
      <dynamics damping="${head_damping}" friction="${head_friction}"/> <!--TODO: Tune-->
    </joint>
    
       <!-- Head Sonar -->
   <xacro:range_reem name="head_sonar_20" parent="${name}" ros_topic="sonar_torso" update_rate="5" maxRange="1.5" minRange="0.0" fov="0.3491" radiation="ultrasound">
      <origin xyz="0.086 -0.195 0.0" rpy="1.57 0.0 0.0" />
   </xacro:range_reem> 

    <!-- extensions -->
    <xacro:reem_head_2_gazebo name="${name}" />
    <xacro:reem_head_2_transmission name="${name}" />

    </xacro:macro>

  <xacro:macro name="reem_head" params="name parent">
    <xacro:reem_head_1 name="${name}_1" parent="${parent}" />
    <xacro:reem_head_2 name="${name}_2" parent="${name}_1_link"/>
  </xacro:macro>

</robot>
